Workbook

Sheet CATALOGO FERIA
A1: INVENTARIO LA TABA
A2: Catálogo de muebles y objetos
D3: ACTUALIZADO: | E3: 24/09/2026
A5: Imagen | B5: Objeto | C5: Descripción | D5: Valor Nuevo | E5: Valor Usado
A6: Dormitorio 2
B7: Sommier 2 Plazas | C7: Sommier en buen estado | E7: 350000
B8: Respaldo negro | C8: Respaldo negro en perfecto estado | E8: 60000
B9: Mesa de luz Blanca | C9: Comoda con cajon blanca | E9: 50000
B10: Mesa de luz Blanca | C10: Comoda con cajon blanca | E10: 50000
B11: Velador artesanal — x2 | C11: Velador artesanal | E11: 100000
B12: Cuadro caballo blanco | C12: Cuadro caballo grande | E12: 100000
B13: Cuna + Cambiador + Cajonera | C13: Cuna con colchon, cambiador y cajones | E13: 250000
B14: Escritorio | C14: Escritorio blanco con cajones | E14: 120000
B15: Sillon Matero de un cuerpo | C15: Un cuerpo color beige | E15: 150000
B16: TV Admiral 32' | C16: TV 32' Admiral | E16: 150000
B17: Estufa electrica ATMA | C17: Estufa atma con ruedas | E17: 120000
A18: Dormitorio 3
B19: Mesa de luz blanca | C19: Comoda con cajon blanca | E19: 50000
B20: Velador artesanal | C20: Velador artesanal | E20: 50000
A21: Sin ambiente informado
A22: AGREGAR FOTO
A23: Dormitorio 4
A24: AGREGAR FOTO | B24: Mesa de luz blanca | C24: Comoda con cajon blanca | E24: 50000
B25: Velador artesanal | C25: Velador artesanal de hierro con campana | E25: 100000
B26: Cuadro Conejo | C26: Cuadro conejo | E26: 50000
B27: Cama de Hierro negro 1 Plaza + colchon — x2 | C27: cama de hierro negro mas colchon en buen estado | E27: 200000
A28: Dormitorio 5
B29: Mesa de luz blanca — x2 | C29: Comoda con cajon blanca | E29: 100000
B30: Sommier 2 Plazas | C30: Sommier 2P en buen estado | E30: 350000
B31: Velador artesanal | C31: Velador artesanal | E31: 50000
B32: Estufa electrica ATMA | C32: Estufa atma con ruedas | E32: 120000
B33: Aplique de pared rustico | C33: Aplique de pared con tirador | E33: 100000
A34: Dormitorio 6
B35: Cama de madera 1 Plaza — x2 | C35: Cama de madera 1 Plaza con respaldo | E35: 200000
B36: Mesa de luz Blanca chica | C36: Mesa de luz blanca chica | E36: 35000
B37: Velador artesanal | C37: Velador artesanal | E37: 50000
B38: Cuadro oveja | C38: Cuadro de oveja | E38: 50000
A39: Dormitorio 7
B40: Cama de madera 1 Plaza — x2 | C40: Cama de madera 1 Plaza con respaldo | E40: 200000
B41: Mesa de luz blanca | C41: Mesa de luz blanca con cajon | E41: 50000
...

Sheet RESUMEN
B2: INVENTARIO — ESTANCIA LA TABA
B4: INDICADORES GENERALES | E4: CONTROL DE VENTA | H4: ORDEN DE RELEVAMIENTO
B5: Registros cargados | C5: =COUNTIF(INVENTARIO!A2:A1000,"<>") -> 138 | E5: Valor publicado vendido ($) | F5: =C15 -> 0 | H5: 1. Recorrer un ambiente completo antes de pasar al siguiente.
B6: Unidades totales | C6: =SUM(INVENTARIO!F2:F1000) -> 540 | E6: Valor publicado pendiente ($) | F6: =C13-C15 -> 50880000 | H6: 2. Asignar un ID único a cada artículo o lote.
B7: Disponibles | C7: =COUNTIF(INVENTARIO!J2:J1000,"Disponible") -> 126 | E7: Porcentaje de unidades vendidas | F7: =IFERROR(COUNTIF(INVENTARIO!J2:J1000,"Vendido")/COUNTIF(INVENTARIO!A2:A1000,"<>"),0) -> 0 | H7: 3. Fotografiar cada pieza y nombrar las fotos con su ID.
B8: Reservados | C8: =COUNTIF(INVENTARIO!J2:J1000,"Reservado") -> 0 | H8: 4. Medir muebles grandes y anotar desperfectos.
B9: Vendidos | C9: =COUNTIF(INVENTARIO!J2:J1000,"Vendido") -> 0 | H9: 5. Marcar el nivel de valor: Alto / Medio / Bajo.
B10: Retirados | C10: =COUNTIF(INVENTARIO!J2:J1000,"Retirado") -> 0 | H10: 6. Definir si se publica en el catálogo.
B11: No vender | C11: =COUNTIF(INVENTARIO!J2:J1000,"No vender") -> 0 | H11: 7. Colocar una etiqueta física con el ID y precio.
B12: Publicados | C12: =COUNTIF(INVENTARIO!K2:K1000,"Sí") -> 125 | H12: 8. Durante la feria actualizar Estado de venta y datos del comprador.
B13: Valor total publicado ($) | C13: =SUMPRODUCT(INVENTARIO!F2:F1000,INVENTARIO!I2:I1000) -> 50880000
B14: Valor publicado disponible ($) | C14: =SUMPRODUCT((INVENTARIO!J2:J1000="Disponible")*INVENTARIO!F2:F1000*INVENTARIO!I2:I1000) -> 45010000
B15: Valor publicado vendido ($) | C15: =SUMPRODUCT((INVENTARIO!J2:J1000="Vendido")*INVENTARIO!F2:F1000*INVENTARIO!I2:I1000) -> 0
B18: RESUMEN POR AMBIENTE
B19: Ambiente | C19: Registros | D19: Vendidos | E19: Disponibles | F19: Valor publicado
B20: Casco / Casa principal | C20: =COUNTIF(INVENTARIO!B2:B1000,B20) -> 0 | D20: =COUNTIFS(INVENTARIO!B2:B1000,B20,INVENTARIO!J2:J1000,"Vendido") -> 0 | E20: =COUNTIFS(INVENTARIO!B2:B1000,B20,INVENTARIO!J2:J1000,"Disponible") -> 0 | F20: =SUMPRODUCT((INVENTARIO!B2:B1000=B20)*INVENTARIO!F2:F1000*INVENTARIO!I2:I1000) -> 0
B21: Living principal | C21: =COUNTIF(INVENTARIO!B2:B1000,B21) -> 5 | D21: =COUNTIFS(INVENTARIO!B2:B1000,B21,INVENTARIO!J2:J1000,"Vendido") -> 0 | E21: =COUNTIFS(INVENTARIO!B2:B1000,B21,INVENTARIO!J2:J1000,"Disponible") -> 5 | F21: =SUMPRODUCT((INVENTARIO!B2:B1000=B21)*INVENTARIO!F2:F1000*INVENTARIO!I2:I1000) -> 4330000
B22: Living secundario | C22: =COUNTIF(INVENTARIO!B2:B1000,B22) -> 5 | D22: =COUNTIFS(INVENTARIO!B2:B1000,B22,INVENTARIO!J2:J1000,"Vendido") -> 0 | E22: =COUNTIFS(INVENTARIO!B2:B1000,B22,INVENTARIO!J2:J1000,"Disponible") -> 5 | F22: =SUMPRODUCT((INVENTARIO!B2:B1000=B22)*INVENTARIO!F2:F1000*INVENTARIO!I2:I1000) -> 530000
B23: Comedor principal | C23: =COUNTIF(INVENTARIO!B2:B1000,B23) -> 3 | D23: =COUNTIFS(INVENTARIO!B2:B1000,B23,INVENTARIO!J2:J1000,"Vendido") -> 0 | E23: =COUNTIFS(INVENTARIO!B2:B1000,B23,INVENTARIO!J2:J1000,"Disponible") -> 3 | F23: =SUMPRODUCT((INVENTARIO!B2:B1000=B23)*INVENTARIO!F2:F1000*INVENTARIO!I2:I1000) -> 1000000
B24: Comedor secundario | C24: =COUNTIF(INVENTARIO!B2:B1000,B24) -> 0 | D24: =COUNTIFS(INVENTARIO!B2:B1000,B24,INVENTARIO!J2:J1000,"Vendido") -> 0 | E24: =COUNTIFS(INVENTARIO!B2:B1000,B24,INVENTARIO!J2:J1000,"Disponible") -> 0 | F24: =SUMPRODUCT((INVENTARIO!B2:B1000=B24)*INVENTARIO!F2:F1000*INVENTARIO!I2:I1000) -> 0
B25: Cocina | C25: =COUNTIF(INVENTARIO!B2:B1000,B25) -> 24 | D25: =COUNTIFS(INVENTARIO!B2:B1000,B25,INVENTARIO!J2:J1000,"Vendido") -> 0 | E25: =COUNTIFS(INVENTARIO!B2:B1000,B25,INVENTARIO!J2:J1000,"Disponible") -> 24 | F25: =SUMPRODUCT((INVENTARIO!B2:B1000=B25)*INVENTARIO!F2:F1000*INVENTARIO!I2:I1000) -> 23205000
B26: Dormitorio principal | C26: =COUNTIF(INVENTARIO!B2:B1000,B26) -> 8 | D26: =COUNTIFS(INVENTARIO!B2:B1000,B26,INVENTARIO!J2:J1000,"Vendido") -> 0 | E26: =COUNTIFS(INVENTARIO!B2:B1000,B26,INVENTARIO!J2:J1000,"Disponible") -> 8 | F26: =SUMPRODUCT((INVENTARIO!B2:B1000=B26)*INVENTARIO!F2:F1000*INVENTARIO!I2:I1000) -> 1545000
B27: Dormitorio 2 | C27: =COUNTIF(INVENTARIO!B2:B1000,B27) -> 11 | D27: =COUNTIFS(INVENTARIO!B2:B1000,B27,INVENTARIO!J2:J1000,"Vendido") -> 0 | E27: =COUNTIFS(INVENTARIO!B2:B1000,B27,INVENTARIO!J2:J1000,"Disponible") -> 11 | F27: =SUMPRODUCT((INVENTARIO!B2:B1000=B27)*INVENTARIO!F2:F1000*INVENTARIO!I2:I1000) -> 1600000
B28: Dormitorio 3 | C28: =COUNTIF(INVENTARIO!B2:B1000,B28) -> 2 | D28: =COUNTIFS(INVENTARIO!B2:B1000,B28,INVENTARIO!J2:J1000,"Vendido") -> 0 | E28: =COUNTIFS(INVENTARIO!B2:B1000,B28,INVENTARIO!J2:J1000,"Disponible") -> 2 | F28: =SUMPRODUCT((INVENTARIO!B2:B1000=B28)*INVENTARIO!F2:F1000*INVENTARIO!I2:I1000) -> 100000
B29: Dormitorio 4 | C29: =COUNTIF(INVENTARIO!B2:B1000,B29) -> 4 | D29: =COUNTIFS(INVENTARIO!B2:B1000,B29,INVENTARIO!J2:J1000,"Vendido") -> 0 | E29: =COUNTIFS(INVENTARIO!B2:B1000,B29,INVENTARIO!J2:J1000,"Disponible") -> 4 | F29: =SUMPRODUCT((INVENTARIO!B2:B1000=B29)*INVENTARIO!F2:F1000*INVENTARIO!I2:I1000) -> 150000
B30: Dormitorio 5 | C30: =COUNTIF(INVENTARIO!B2:B1000,B30) -> 5 | D30: =COUNTIFS(INVENTARIO!B2:B1000,B30,INVENTARIO!J2:J1000,"Vendido") -> 0 | E30: =COUNTIFS(INVENTARIO!B2:B1000,B30,INVENTARIO!J2:J1000,"Disponible") -> 5 | F30: =SUMPRODUCT((INVENTARIO!B2:B1000=B30)*INVENTARIO!F2:F1000*INVENTARIO!I2:I1000) -> 820000
B31: Dormitorio 6 | C31: =COUNTIF(INVENTARIO!B2:B1000,B31) -> 4 | D31: =COUNTIFS(INVENTARIO!B2:B1000,B31,INVENTARIO!J2:J1000,"Vendido") -> 0 | E31: =COUNTIFS(INVENTARIO!B2:B1000,B31,INVENTARIO!J2:J1000,"Disponible") -> 4 | F31: =SUMPRODUCT((INVENTARIO!B2:B1000=B31)*INVENTARIO!F2:F1000*INVENTARIO!I2:I1000) -> 535000
B32: Dormitorio 7 | C32: =COUNTIF(INVENTARIO!B2:B1000,B32) -> 4 | D32: =COUNTIFS(INVENTARIO!B2:B1000,B32,INVENTARIO!J2:J1000,"Vendido") -> 0 | E32: =COUNTIFS(INVENTARIO!B2:B1000,B32,INVENTARIO!J2:J1000,"Disponible") -> 4 | F32: =SUMPRODUCT((INVENTARIO!B2:B1000=B32)*INVENTARIO!F2:F1000*INVENTARIO!I2:I1000) -> 550000
B33: Dormitorio 8 | C33: =COUNTIF(INVENTARIO!B2:B1000,B33) -> 4 | D33: =COUNTIFS(INVENTARIO!B2:B1000,B33,INVENTARIO!J2:J1000,"Vendido") -> 0 | E33: =COUNTIFS(INVENTARIO!B2:B1000,B33,INVENTARIO!J2:J1000,"Disponible") -> 4 | F33: =SUMPRODUCT((INVENTARIO!B2:B1000=B33)*INVENTARIO!F2:F1000*INVENTARIO!I2:I1000) -> 420000
B34: Dormitorio 9 | C34: =COUNTIF(INVENTARIO!B2:B1000,B34) -> 8 | D34: =COUNTIFS(INVENTARIO!B2:B1000,B34,INVENTARIO!J2:J1000,"Vendido") -> 0 | E34: =COUNTIFS(INVENTARIO!B2:B1000,B34,INVENTARIO!J2:J1000,"Disponible") -> 8 | F34: =SUMPRODUCT((INVENTARIO!B2:B1000=B34)*INVENTARIO!F2:F1000*INVENTARIO!I2:I1000) -> 860000
B35: Dormitorio 10 | C35: =COUNTIF(INVENTARIO!B2:B1000,B35) -> 5 | D35: =COUNTIFS(INVENTARIO!B2:B1000,B35,INVENTARIO!J2:J1000,"Vendido") -> 0 | E35: =COUNTIFS(INVENTARIO!B2:B1000,B35,INVENTARIO!J2:J1000,"Disponible") -> 5 | F35: =SUMPRODUCT((INVENTARIO!B2:B1000=B35)*INVENTARIO!F2:F1000*INVENTARIO!I2:I1000) -> 710000
B36: Baño 1 | C36: =COUNTIF(INVENTARIO!B2:B1000,B36) -> 0 | D36: =COUNTIFS(INVENTARIO!B2:B1000,B36,INVENTARIO!J2:J1000,"Vendido") -> 0 | E36: =COUNTIFS(INVENTARIO!B2:B1000,B36,INVENTARIO!J2:J1000,"Disponible") -> 0 | F36: =SUMPRODUCT((INVENTARIO!B2:B1000=B36)*INVENTARIO!F2:F1000*INVENTARIO!I2:I1000) -> 0
B37: Baño 2 | C37: =COUNTIF(INVENTARIO!B2:B1000,B37) -> 0 | D37: =COUNTIFS(INVENTARIO!B2:B1000,B37,INVENTARIO!J2:J1000,"Vendido") -> 0 | E37: =COUNTIFS(INVENTARIO!B2:B1000,B37,INVENTARIO!J2:J1000,"Disponible") -> 0 | F37: =SUMPRODUCT((INVENTARIO!B2:B1000=B37)*INVENTARIO!F2:F1000*INVENTARIO!I2:I1000) -> 0
B38: Baño 3 | C38: =COUNTIF(INVENTARIO!B2:B1000,B38) -> 0 | D38: =COUNTIFS(INVENTARIO!B2:B1000,B38,INVENTARIO!J2:J1000,"Vendido") -> 0 | E38: =COUNTIFS(INVENTARIO!B2:B1000,B38,INVENTARIO!J2:J1000,"Disponible") -> 0 | F38: =SUMPRODUCT((INVENTARIO!B2:B1000=B38)*INVENTARIO!F2:F1000*INVENTARIO!I2:I1000) -> 0
B39: Baño 4 | C39: =COUNTIF(INVENTARIO!B2:B1000,B39) -> 0 | D39: =COUNTIFS(INVENTARIO!B2:B1000,B39,INVENTARIO!J2:J1000,"Vendido") -> 0 | E39: =COUNTIFS(INVENTARIO!B2:B1000,B39,INVENTARIO!J2:J1000,"Disponible") -> 0 | F39: =SUMPRODUCT((INVENTARIO!B2:B1000=B39)*INVENTARIO!F2:F1000*INVENTARIO!I2:I1000) -> 0
B40: Baño 5 | C40: =COUNTIF(INVENTARIO!B2:B1000,B40) -> 0 | D40: =COUNTIFS(INVENTARIO!B2:B1000,B40,INVENTARIO!J2:J1000,"Vendido") -> 0 | E40: =COUNTIFS(INVENTARIO!B2:B1000,B40,INVENTARIO!J2:J1000,"Disponible") -> 0 | F40: =SUMPRODUCT((INVENTARIO!B2:B1000=B40)*INVENTARIO!F2:F1000*INVENTARIO!I2:I1000) -> 0
B41: Baño 6 | C41: =COUNTIF(INVENTARIO!B2:B1000,B41) -> 0 | D41: =COUNTIFS(INVENTARIO!B2:B1000,B41,INVENTARIO!J2:J1000,"Vendido") -> 0 | E41: =COUNTIFS(INVENTARIO!B2:B1000,B41,INVENTARIO!J2:J1000,"Disponible") -> 0 | F41: =SUMPRODUCT((INVENTARIO!B2:B1000=B41)*INVENTARIO!F2:F1000*INVENTARIO!I2:I1000) -> 0
B42: Baño 7 | C42: =COUNTIF(INVENTARIO!B2:B1000,B42) -> 0 | D42: =COUNTIFS(INVENTARIO!B2:B1000,B42,INVENTARIO!J2:J1000,"Vendido") -> 0 | E42: =COUNTIFS(INVENTARIO!B2:B1000,B42,INVENTARIO!J2:J1000,"Disponible") -> 0 | F42: =SUMPRODUCT((INVENTARIO!B2:B1000=B42)*INVENTARIO!F2:F1000*INVENTARIO!I2:I1000) -> 0
B43: Baño 8 | C43: =COUNTIF(INVENTARIO!B2:B1000,B43) -> 0 | D43: =COUNTIFS(INVENTARIO!B2:B1000,B43,INVENTARIO!J2:J1000,"Vendido") -> 0 | E43: =COUNTIFS(INVENTARIO!B2:B1000,B43,INVENTARIO!J2:J1000,"Disponible") -> 0 | F43: =SUMPRODUCT((INVENTARIO!B2:B1000=B43)*INVENTARIO!F2:F1000*INVENTARIO!I2:I1000) -> 0
B44: Galería | C44: =COUNTIF(INVENTARIO!B2:B1000,B44) -> 2 | D44: =COUNTIFS(INVENTARIO!B2:B1000,B44,INVENTARIO!J2:J1000,"Vendido") -> 0 | E44: =COUNTIFS(INVENTARIO!B2:B1000,B44,INVENTARIO!J2:J1000,"Disponible") -> 2 | F44: =SUMPRODUCT((INVENTARIO!B2:B1000=B44)*INVENTARIO!F2:F1000*INVENTARIO!I2:I1000) -> 1000000
...

Sheet INVENTARIO
A1: ID | B1: Ambiente | C1: Categoría | D1: Artículo | E1: Descripción | F1: Cantidad | G1: Medidas | H1: Estado | I1: Precio publicado | J1: Estado de venta | K1: Publicar | L1: Foto principal (insertar en celda) | M1: Fotos adicionales
A2: EST-001 | B2: Dormitorio 2 | C2: Muebles | D2: Sommier 2 Plazas | E2: Sommier en buen estado | F2: 1 | G2: 2 Plazas | I2: 350000 | J2: Disponible | K2: Sí | L2: EST-001.jpg
A3: EST-002 | B3: Dormitorio 2 | C3: Muebles | D3: Respaldo negro | E3: Respaldo negro en perfecto estado | F3: 1 | G3: 2 Plazas | H3: Buen estado | I3: 60000 | J3: Disponible | K3: Sí | L3: EST-002.jpg
A4: EST-003 | B4: Dormitorio 2 | C4: Muebles | D4: Mesa de luz Blanca | E4: Comoda con cajon blanca | F4: 1 | G4: 43x31x65 | H4: Buen estado | I4: 50000 | J4: Disponible | K4: Sí | L4: EST-003.jpg
A5: EST-004 | B5: Dormitorio 2 | C5: Muebles | D5: Mesa de luz Blanca | E5: Comoda con cajon blanca | F5: 1 | G5: 43x31x65 | H5: Despintada | I5: 50000 | J5: Disponible | K5: Sí | L5: EST-004.jpg
A6: EST-005 | B6: Dormitorio 2 | C6: Iluminacion | D6: Velador artesanal | E6: Velador artesanal | F6: 2 | H6: Buen estado | I6: 100000 | J6: Disponible | K6: Sí | L6: EST-005.jpg
A7: EST-006 | B7: Dormitorio 2 | C7: Cuadros caballos | D7: Cuadro caballo blanco | E7: Cuadro caballo grande | F7: 1 | H7: Buen estado | I7: 100000 | J7: Disponible | K7: Sí | L7: EST-006.jpg
A8: EST-007 | B8: Dormitorio 2 | C8: Muebles | D8: Cuna + Cambiador + Cajonera | E8: Cuna con colchon, cambiador y cajones | F8: 1 | H8: Sin detalles | I8: 250000 | J8: Disponible | K8: Sí | L8: EST-007.jpg
A9: EST-008 | B9: Dormitorio 2 | C9: Muebles | D9: Escritorio | E9: Escritorio blanco con cajones | F9: 1 | H9: Buen estado | I9: 120000 | J9: Disponible | K9: Sí | L9: EST-008.jpg
A10: EST-009 | B10: Dormitorio 2 | C10: Muebles | D10: Sillon Matero de un cuerpo | E10: Un cuerpo color beige | F10: 1 | H10: Buen estado | I10: 150000 | J10: Disponible | K10: Sí | L10: EST-009.jpg
A11: EST-010 | B11: Dormitorio 2 | C11: Electrodimesticos | D11: TV Admiral 32' | E11: TV 32' Admiral | F11: 1 | G11: 32' | H11: Buen estado | I11: 150000 | J11: Disponible | K11: Sí | L11: EST-010.jpg
A12: EST-011 | B12: Dormitorio 2 | C12: Electrodimesticos | D12: Estufa electrica ATMA | E12: Estufa atma con ruedas | F12: 1 | H12: Buen estado | I12: 120000 | J12: Disponible | K12: Sí | L12: EST-011.jpg
A13: EST-012 | B13: Dormitorio 3 | C13: Muebles | D13: Mesa de luz blanca | E13: Comoda con cajon blanca | F13: 1 | G13: 43x31x65 | H13: Buen estado | I13: 50000 | J13: Disponible | K13: Sí | L13: EST-012.jpg
A14: EST-013 | B14: Dormitorio 3 | C14: Iluminacion | D14: Velador artesanal | E14: Velador artesanal | F14: 1 | H14: Buen estado | I14: 50000 | J14: Disponible | K14: Sí | L14: EST-013.jpg
A15: EST-014 | J15: Disponible | K15: Sí
A16: EST-015 | B16: Dormitorio 4 | C16: Muebles | D16: Mesa de luz blanca | E16: Comoda con cajon blanca | F16: 1 | G16: 43x31x65 | H16: Buen estado | I16: 50000 | J16: Disponible | K16: Sí | L16: EST-015.jpg
A17: EST-016 | B17: Dormitorio 4 | C17: Iluminacion | D17: Velador artesanal | E17: Velador artesanal de hierro con campana | F17: 1 | H17: Buen estado | I17: 100000 | J17: Disponible | K17: Sí | L17: EST-016.jpg
A18: EST-017 | B18: Dormitorio 4 | C18: Cuadro animales | D18: Cuadro Conejo | E18: Cuadro conejo | F18: 1 | H18: Buen estado | J18: Disponible | K18: Sí
A19: EST-018 | B19: Dormitorio 4 | C19: Muebles | D19: Cama de Hierro negro 1 Plaza + colchon | E19: cama de hierro negro mas colchon en buen estado | F19: 2 | G19: 1 Plaza | H19: Buen estado | J19: Disponible | K19: Sí
A20: EST-019 | B20: Dormitorio 5 | C20: Muebles | D20: Mesa de luz blanca | E20: Comoda con cajon blanca | F20: 2 | G20: 43x31x65 | H20: Buen estado | I20: 100000 | J20: Disponible | K20: Sí
A21: EST-020 | B21: Dormitorio 5 | C21: Muebles | D21: Sommier 2 Plazas | E21: Sommier 2P en buen estado | F21: 1 | G21: 2 Plazas | H21: Buen estado | I21: 350000 | J21: Disponible | K21: Sí
A22: EST-021 | B22: Dormitorio 5 | C22: Iluminacion | D22: Velador artesanal | E22: Velador artesanal | F22: 1 | H22: Buen estado | I22: 50000 | J22: Disponible | K22: Sí
A23: EST-022 | B23: Dormitorio 5 | C23: Electrodimesticos | D23: Estufa electrica ATMA | E23: Estufa atma con ruedas | F23: 1 | H23: Buen estado | I23: 120000 | J23: Disponible | K23: Sí
A24: EST-023 | B24: Dormitorio 5 | C24: Iluminacion | D24: Aplique de pared rustico | E24: Aplique de pared con tirador | F24: 1 | H24: Buen estado | I24: 100000 | J24: Disponible | K24: Sí
A25: EST-024 | B25: Dormitorio 6 | C25: Muebles | D25: Cama de madera 1 Plaza | E25: Cama de madera 1 Plaza con respaldo | F25: 2 | G25: 1 Plaza | H25: Buen estado | I25: 200000 | J25: Disponible | K25: Sí
A26: EST-025 | B26: Dormitorio 6 | C26: Muebles | D26: Mesa de luz Blanca chica | E26: Mesa de luz blanca chica | F26: 1 | G26: 35x30x60 | H26: Despintada | I26: 35000 | J26: Disponible | K26: Sí
A27: EST-026 | B27: Dormitorio 6 | C27: Iluminacion | D27: Velador | E27: Velador artesanal | F27: 1 | H27: Buen estado | I27: 50000 | J27: Disponible | K27: Sí
A28: EST-027 | B28: Dormitorio 6 | C28: Cuadro animales | D28: Cuadro oveja | E28: Cuadro de oveja | F28: 1 | H28: Buen estado | I28: 50000 | J28: Disponible | K28: Sí
A29: EST-028 | B29: Dormitorio 7 | C29: Muebles | D29: Cama de madera 1 Plaza | E29: Cama de madera 1 Plaza con respaldo | F29: 2 | G29: 1 Plaza | H29: Buen estado | I29: 200000 | J29: Disponible | K29: Sí
A30: EST-029 | B30: Dormitorio 7 | C30: Muebles | D30: Mesa de luz blanca | E30: Mesa de luz blanca con cajon | F30: 1 | G30: 43x31x65 | H30: Buen estado | I30: 50000 | J30: Disponible | K30: Sí
A31: EST-030 | B31: Dormitorio 7 | C31: Iluminacion | D31: Velador artesanal | E31: Velador artesanal de hierro con campana | F31: 1 | H31: Buen estado | I31: 50000 | J31: Disponible | K31: Sí
A32: EST-031 | B32: Dormitorio 7 | C32: Cuadro animales | D32: Cuadro vaca | E32: Cuadro de vaca marco de madera | F32: 1 | H32: Buen estado | I32: 50000 | J32: Disponible | K32: Sí
A33: EST-032 | B33: Dormitorio 8 | C33: Muebles | D33: Cama de madera 1 plaza con camastro y 3 cajones | E33: Cama de 1 plaza con camastro y 3 cajones | F33: 1 | G33: 1 Plaza | H33: Buen estado | I33: 200000 | J33: Disponible | K33: Sí
A34: EST-033 | B34: Dormitorio 8 | C34: Muebles | D34: Cama de hierro 1 Plaza | E34: Cama con base de hierro 1 Plaza | F34: 1 | G34: 1 Plaza | H34: Buen estado | I34: 120000 | J34: Disponible | K34: Sí
A35: EST-034 | B35: Dormitorio 8 | C35: Muebles | D35: Cofre de madera blanco | E35: Cofre de madera | F35: 1 | G35: 50x50x50 | H35: Buen estado | I35: 50000 | J35: Disponible | K35: Sí
A36: EST-035 | B36: Dormitorio 8 | C36: Cuadro animales | D36: Cuadro oveja | E36: Cuadro de oveja marco de madera | F36: 1 | H36: Buen estado | I36: 50000 | J36: Disponible | K36: Sí
A37: EST-036 | B37: Living altillo | C37: Muebles | D37: Sillon cama verde | E37: Sillon cama verde plegable | F37: 1 | H37: Roto pero funcional | I37: 120000 | J37: Disponible | K37: Sí
A38: EST-037 | B38: Living altillo | C38: Muebles | D38: Sillon cama amarillo | E38: Sillon cama amarillo plegable | F38: 1 | H38: Buen estado | I38: 150000 | J38: Disponible | K38: Sí
A39: EST-038 | B39: Living altillo | C39: Muebles | D39: Mesa ratona de madera | E39: Mesa ratona de madera | F39: 1 | G39: 100x60x40 | H39: Buen estado | I39: 80000 | J39: Disponible | K39: Sí
A40: EST-039 | B40: Living altillo | C40: Cuadros caballos | D40: Cuadro caballos amanecer | E40: Cuadro caballos amanecer | F40: 1 | H40: Buen estado | I40: 100000 | J40: Disponible | K40: Sí
...

Sheet VENTAS
A1: ID | B1: Artículo | C1: Ambiente | D1: Tipo | E1: Precio publicado | F1: Precio vendido | G1: Diferencia | H1: Comprador | I1: Fecha | J1: Forma de pago | K1: Estado | L1: Observaciones
A2: =IF(INVENTARIO!A2="","",INVENTARIO!A2) -> EST-001 | B2: =IF(INVENTARIO!G2="","",INVENTARIO!G2) -> 2 Plazas | C2: =IF(INVENTARIO!B2="","",INVENTARIO!B2) -> Dormitorio 2 | D2: =IF(INVENTARIO!D2="","",INVENTARIO!D2) -> Sommier 2 Plazas | E2: =IF(INVENTARIO!O2="","",INVENTARIO!O2) | F2: =IF(INVENTARIO!Q2="","",INVENTARIO!Q2) | G2: =IF(OR(E2="",F2=""),"",E2-F2) | H2: =IF(INVENTARIO!T2="","",INVENTARIO!T2) | I2: =IF(INVENTARIO!U2="","",INVENTARIO!U2) | J2: =IF(INVENTARIO!V2="","",INVENTARIO!V2) | K2: =IF(INVENTARIO!R2="","",INVENTARIO!R2) | L2: =IF(INVENTARIO!Y2="","",INVENTARIO!Y2)
A3: =IF(INVENTARIO!A3="","",INVENTARIO!A3) -> EST-002 | B3: =IF(INVENTARIO!G3="","",INVENTARIO!G3) -> 2 Plazas | C3: =IF(INVENTARIO!B3="","",INVENTARIO!B3) -> Dormitorio 2 | D3: =IF(INVENTARIO!D3="","",INVENTARIO!D3) -> Respaldo negro | E3: =IF(INVENTARIO!O3="","",INVENTARIO!O3) | F3: =IF(INVENTARIO!Q3="","",INVENTARIO!Q3) | G3: =IF(OR(E3="",F3=""),"",E3-F3) | H3: =IF(INVENTARIO!T3="","",INVENTARIO!T3) | I3: =IF(INVENTARIO!U3="","",INVENTARIO!U3) | J3: =IF(INVENTARIO!V3="","",INVENTARIO!V3) | K3: =IF(INVENTARIO!R3="","",INVENTARIO!R3) | L3: =IF(INVENTARIO!Y3="","",INVENTARIO!Y3)
A4: =IF(INVENTARIO!A4="","",INVENTARIO!A4) -> EST-003 | B4: =IF(INVENTARIO!G4="","",INVENTARIO!G4) -> 43x31x65 | C4: =IF(INVENTARIO!B4="","",INVENTARIO!B4) -> Dormitorio 2 | D4: =IF(INVENTARIO!D4="","",INVENTARIO!D4) -> Mesa de luz Blanca | E4: =IF(INVENTARIO!O4="","",INVENTARIO!O4) | F4: =IF(INVENTARIO!Q4="","",INVENTARIO!Q4) | G4: =IF(OR(E4="",F4=""),"",E4-F4) | H4: =IF(INVENTARIO!T4="","",INVENTARIO!T4) | I4: =IF(INVENTARIO!U4="","",INVENTARIO!U4) | J4: =IF(INVENTARIO!V4="","",INVENTARIO!V4) | K4: =IF(INVENTARIO!R4="","",INVENTARIO!R4) | L4: =IF(INVENTARIO!Y4="","",INVENTARIO!Y4)
A5: =IF(INVENTARIO!A5="","",INVENTARIO!A5) -> EST-004 | B5: =IF(INVENTARIO!G5="","",INVENTARIO!G5) -> 43x31x65 | C5: =IF(INVENTARIO!B5="","",INVENTARIO!B5) -> Dormitorio 2 | D5: =IF(INVENTARIO!D5="","",INVENTARIO!D5) -> Mesa de luz Blanca | E5: =IF(INVENTARIO!O5="","",INVENTARIO!O5) | F5: =IF(INVENTARIO!Q5="","",INVENTARIO!Q5) | G5: =IF(OR(E5="",F5=""),"",E5-F5) | H5: =IF(INVENTARIO!T5="","",INVENTARIO!T5) | I5: =IF(INVENTARIO!U5="","",INVENTARIO!U5) | J5: =IF(INVENTARIO!V5="","",INVENTARIO!V5) | K5: =IF(INVENTARIO!R5="","",INVENTARIO!R5) | L5: =IF(INVENTARIO!Y5="","",INVENTARIO!Y5)
A6: =IF(INVENTARIO!A6="","",INVENTARIO!A6) -> EST-005 | B6: =IF(INVENTARIO!G6="","",INVENTARIO!G6) | C6: =IF(INVENTARIO!B6="","",INVENTARIO!B6) -> Dormitorio 2 | D6: =IF(INVENTARIO!D6="","",INVENTARIO!D6) -> Velador artesanal | E6: =IF(INVENTARIO!O6="","",INVENTARIO!O6) | F6: =IF(INVENTARIO!Q6="","",INVENTARIO!Q6) | G6: =IF(OR(E6="",F6=""),"",E6-F6) | H6: =IF(INVENTARIO!T6="","",INVENTARIO!T6) | I6: =IF(INVENTARIO!U6="","",INVENTARIO!U6) | J6: =IF(INVENTARIO!V6="","",INVENTARIO!V6) | K6: =IF(INVENTARIO!R6="","",INVENTARIO!R6) | L6: =IF(INVENTARIO!Y6="","",INVENTARIO!Y6)
A7: =IF(INVENTARIO!A7="","",INVENTARIO!A7) -> EST-006 | B7: =IF(INVENTARIO!G7="","",INVENTARIO!G7) | C7: =IF(INVENTARIO!B7="","",INVENTARIO!B7) -> Dormitorio 2 | D7: =IF(INVENTARIO!D7="","",INVENTARIO!D7) -> Cuadro caballo blanco | E7: =IF(INVENTARIO!O7="","",INVENTARIO!O7) | F7: =IF(INVENTARIO!Q7="","",INVENTARIO!Q7) | G7: =IF(OR(E7="",F7=""),"",E7-F7) | H7: =IF(INVENTARIO!T7="","",INVENTARIO!T7) | I7: =IF(INVENTARIO!U7="","",INVENTARIO!U7) | J7: =IF(INVENTARIO!V7="","",INVENTARIO!V7) | K7: =IF(INVENTARIO!R7="","",INVENTARIO!R7) | L7: =IF(INVENTARIO!Y7="","",INVENTARIO!Y7)
A8: =IF(INVENTARIO!A8="","",INVENTARIO!A8) -> EST-007 | B8: =IF(INVENTARIO!G8="","",INVENTARIO!G8) | C8: =IF(INVENTARIO!B8="","",INVENTARIO!B8) -> Dormitorio 2 | D8: =IF(INVENTARIO!D8="","",INVENTARIO!D8) -> Cuna + Cambiador + Cajonera | E8: =IF(INVENTARIO!O8="","",INVENTARIO!O8) | F8: =IF(INVENTARIO!Q8="","",INVENTARIO!Q8) | G8: =IF(OR(E8="",F8=""),"",E8-F8) | H8: =IF(INVENTARIO!T8="","",INVENTARIO!T8) | I8: =IF(INVENTARIO!U8="","",INVENTARIO!U8) | J8: =IF(INVENTARIO!V8="","",INVENTARIO!V8) | K8: =IF(INVENTARIO!R8="","",INVENTARIO!R8) | L8: =IF(INVENTARIO!Y8="","",INVENTARIO!Y8)
A9: =IF(INVENTARIO!A9="","",INVENTARIO!A9) -> EST-008 | B9: =IF(INVENTARIO!G9="","",INVENTARIO!G9) | C9: =IF(INVENTARIO!B9="","",INVENTARIO!B9) -> Dormitorio 2 | D9: =IF(INVENTARIO!D9="","",INVENTARIO!D9) -> Escritorio | E9: =IF(INVENTARIO!O9="","",INVENTARIO!O9) | F9: =IF(INVENTARIO!Q9="","",INVENTARIO!Q9) | G9: =IF(OR(E9="",F9=""),"",E9-F9) | H9: =IF(INVENTARIO!T9="","",INVENTARIO!T9) | I9: =IF(INVENTARIO!U9="","",INVENTARIO!U9) | J9: =IF(INVENTARIO!V9="","",INVENTARIO!V9) | K9: =IF(INVENTARIO!R9="","",INVENTARIO!R9) | L9: =IF(INVENTARIO!Y9="","",INVENTARIO!Y9)
A10: =IF(INVENTARIO!A10="","",INVENTARIO!A10) -> EST-009 | B10: =IF(INVENTARIO!G10="","",INVENTARIO!G10) | C10: =IF(INVENTARIO!B10="","",INVENTARIO!B10) -> Dormitorio 2 | D10: =IF(INVENTARIO!D10="","",INVENTARIO!D10) -> Sillon Matero de un cuerpo | E10: =IF(INVENTARIO!O10="","",INVENTARIO!O10) | F10: =IF(INVENTARIO!Q10="","",INVENTARIO!Q10) | G10: =IF(OR(E10="",F10=""),"",E10-F10) | H10: =IF(INVENTARIO!T10="","",INVENTARIO!T10) | I10: =IF(INVENTARIO!U10="","",INVENTARIO!U10) | J10: =IF(INVENTARIO!V10="","",INVENTARIO!V10) | K10: =IF(INVENTARIO!R10="","",INVENTARIO!R10) | L10: =IF(INVENTARIO!Y10="","",INVENTARIO!Y10)
A11: =IF(INVENTARIO!A11="","",INVENTARIO!A11) -> EST-010 | B11: =IF(INVENTARIO!G11="","",INVENTARIO!G11) -> 32' | C11: =IF(INVENTARIO!B11="","",INVENTARIO!B11) -> Dormitorio 2 | D11: =IF(INVENTARIO!D11="","",INVENTARIO!D11) -> TV Admiral 32' | E11: =IF(INVENTARIO!O11="","",INVENTARIO!O11) | F11: =IF(INVENTARIO!Q11="","",INVENTARIO!Q11) | G11: =IF(OR(E11="",F11=""),"",E11-F11) | H11: =IF(INVENTARIO!T11="","",INVENTARIO!T11) | I11: =IF(INVENTARIO!U11="","",INVENTARIO!U11) | J11: =IF(INVENTARIO!V11="","",INVENTARIO!V11) | K11: =IF(INVENTARIO!R11="","",INVENTARIO!R11) | L11: =IF(INVENTARIO!Y11="","",INVENTARIO!Y11)
A12: =IF(INVENTARIO!A12="","",INVENTARIO!A12) -> EST-011 | B12: =IF(INVENTARIO!G12="","",INVENTARIO!G12) | C12: =IF(INVENTARIO!B12="","",INVENTARIO!B12) -> Dormitorio 2 | D12: =IF(INVENTARIO!D12="","",INVENTARIO!D12) -> Estufa electrica ATMA | E12: =IF(INVENTARIO!O12="","",INVENTARIO!O12) | F12: =IF(INVENTARIO!Q12="","",INVENTARIO!Q12) | G12: =IF(OR(E12="",F12=""),"",E12-F12) | H12: =IF(INVENTARIO!T12="","",INVENTARIO!T12) | I12: =IF(INVENTARIO!U12="","",INVENTARIO!U12) | J12: =IF(INVENTARIO!V12="","",INVENTARIO!V12) | K12: =IF(INVENTARIO!R12="","",INVENTARIO!R12) | L12: =IF(INVENTARIO!Y12="","",INVENTARIO!Y12)
A13: =IF(INVENTARIO!A13="","",INVENTARIO!A13) -> EST-012 | B13: =IF(INVENTARIO!G13="","",INVENTARIO!G13) -> 43x31x65 | C13: =IF(INVENTARIO!B13="","",INVENTARIO!B13) -> Dormitorio 3 | D13: =IF(INVENTARIO!D13="","",INVENTARIO!D13) -> Mesa de luz blanca | E13: =IF(INVENTARIO!O13="","",INVENTARIO!O13) | F13: =IF(INVENTARIO!Q13="","",INVENTARIO!Q13) | G13: =IF(OR(E13="",F13=""),"",E13-F13) | H13: =IF(INVENTARIO!T13="","",INVENTARIO!T13) | I13: =IF(INVENTARIO!U13="","",INVENTARIO!U13) | J13: =IF(INVENTARIO!V13="","",INVENTARIO!V13) | K13: =IF(INVENTARIO!R13="","",INVENTARIO!R13) | L13: =IF(INVENTARIO!Y13="","",INVENTARIO!Y13)
... A77: =IF(INVENTARIO!A77="","",INVENTARIO!A77) -> EST-076 | B77: =IF(INVENTARIO!G77="","",INVENTARIO!G77) -> 200x100x50 | C77: =IF(INVENTARIO!B77="","",INVENTARIO!B77) -> Salon de juegos | D77: =IF(INVENTARIO!D77="","",INVENTARIO!D77) -> Mueble rustico | E77: =IF(INVENTARIO!O77="","",INVENTARIO!O77) | F77: =IF(INVENTARIO!Q77="","",INVENTARIO!Q77) | G77: =IF(OR(E77="",F77=""),"",E77-F77) | H77: =IF(INVENTARIO!T77="","",INVENTARIO!T77) | I77: =IF(INVENTARIO!U77="","",INVENTARIO!U77) | J77: =IF(INVENTARIO!V77="","",INVENTARIO!V77) | K77: =IF(INVENTARIO!R77="","",INVENTARIO!R77) | L77: =IF(INVENTARIO!Y77="","",INVENTARIO!Y77)
A78: =IF(#REF!="","",#REF!) -> #REF! | B78: =IF(#REF!="","",#REF!) -> #REF! | C78: =IF(#REF!="","",#REF!) -> #REF! | D78: =IF(#REF!="","",#REF!) -> #REF! | E78: =IF(INVENTARIO!O78="","",INVENTARIO!O78) | F78: =IF(INVENTARIO!Q78="","",INVENTARIO!Q78) | G78: =IF(OR(E78="",F78=""),"",E78-F78) | H78: =IF(INVENTARIO!T78="","",INVENTARIO!T78) | I78: =IF(INVENTARIO!U78="","",INVENTARIO!U78) | J78: =IF(INVENTARIO!V78="","",INVENTARIO!V78) | K78: =IF(INVENTARIO!R78="","",INVENTARIO!R78) | L78: =IF(INVENTARIO!Y78="","",INVENTARIO!Y78)
A79: =IF(INVENTARIO!A78="","",INVENTARIO!A78) -> EST-078 | B79: =IF(INVENTARIO!G78="","",INVENTARIO!G78) -> 1.90x70 | C79: =IF(INVENTARIO!B78="","",INVENTARIO!B78) -> Resibidor | D79: =IF(INVENTARIO!D78="","",INVENTARIO!D78) -> Sillon 3 cuerpos floreado | E79: =IF(INVENTARIO!O79="","",INVENTARIO!O79) | F79: =IF(INVENTARIO!Q79="","",INVENTARIO!Q79) | G79: =IF(OR(E79="",F79=""),"",E79-F79) | H79: =IF(INVENTARIO!T79="","",INVENTARIO!T79) | I79: =IF(INVENTARIO!U79="","",INVENTARIO!U79) | J79: =IF(INVENTARIO!V79="","",INVENTARIO!V79) | K79: =IF(INVENTARIO!R79="","",INVENTARIO!R79) | L79: =IF(INVENTARIO!Y79="","",INVENTARIO!Y79)
A80: =IF(INVENTARIO!A79="","",INVENTARIO!A79) -> EST-079 | B80: =IF(INVENTARIO!G79="","",INVENTARIO!G79) -> 1 M | C80: =IF(INVENTARIO!B79="","",INVENTARIO!B79) -> Resibidor | D80: =IF(INVENTARIO!D79="","",INVENTARIO!D79) -> Perchero de madera largo | E80: =IF(INVENTARIO!O80="","",INVENTARIO!O80) | F80: =IF(INVENTARIO!Q80="","",INVENTARIO!Q80) | G80: =IF(OR(E80="",F80=""),"",E80-F80) | H80: =IF(INVENTARIO!T80="","",INVENTARIO!T80) | I80: =IF(INVENTARIO!U80="","",INVENTARIO!U80) | J80: =IF(INVENTARIO!V80="","",INVENTARIO!V80) | K80: =IF(INVENTARIO!R80="","",INVENTARIO!R80) | L80: =IF(INVENTARIO!Y80="","",INVENTARIO!Y80)
A81: =IF(INVENTARIO!A80="","",INVENTARIO!A80) -> EST-080 | B81: =IF(INVENTARIO!G80="","",INVENTARIO!G80) | C81: =IF(INVENTARIO!B80="","",INVENTARIO!B80) -> Resibidor | D81: =IF(INVENTARIO!D80="","",INVENTARIO!D80) -> Cuadro caballo | E81: =IF(INVENTARIO!O81="","",INVENTARIO!O81) | F81: =IF(INVENTARIO!Q81="","",INVENTARIO!Q81) | G81: =IF(OR(E81="",F81=""),"",E81-F81) | H81: =IF(INVENTARIO!T81="","",INVENTARIO!T81) | I81: =IF(INVENTARIO!U81="","",INVENTARIO!U81) | J81: =IF(INVENTARIO!V81="","",INVENTARIO!V81) | K81: =IF(INVENTARIO!R81="","",INVENTARIO!R81) | L81: =IF(INVENTARIO!Y81="","",INVENTARIO!Y81)
A82: =IF(#REF!="","",#REF!) -> #REF! | B82: =IF(#REF!="","",#REF!) -> #REF! | C82: =IF(#REF!="","",#REF!) -> #REF! | D82: =IF(#REF!="","",#REF!) -> #REF! | E82: =IF(#REF!="","",#REF!) -> #REF! | F82: =IF(#REF!="","",#REF!) -> #REF! | G82: =IF(OR(E82="",F82=""),"",E82-F82) -> #REF! | H82: =IF(#REF!="","",#REF!) -> #REF! | I82: =IF(#REF!="","",#REF!) -> #REF! | J82: =IF(#REF!="","",#REF!) -> #REF! | K82: =IF(#REF!="","",#REF!) -> #REF! | L82: =IF(#REF!="","",#REF!) -> #REF!
A83: =IF(#REF!="","",#REF!) -> #REF! | B83: =IF(#REF!="","",#REF!) -> #REF! | C83: =IF(#REF!="","",#REF!) -> #REF! | D83: =IF(#REF!="","",#REF!) -> #REF! | E83: =IF(#REF!="","",#REF!) -> #REF! | F83: =IF(#REF!="","",#REF!) -> #REF! | G83: =IF(OR(E83="",F83=""),"",E83-F83) -> #REF! | H83: =IF(#REF!="","",#REF!) -> #REF! | I83: =IF(#REF!="","",#REF!) -> #REF! | J83: =IF(#REF!="","",#REF!) -> #REF! | K83: =IF(#REF!="","",#REF!) -> #REF! | L83: =IF(#REF!="","",#REF!) -> #REF!
A84: =IF(INVENTARIO!A81="","",INVENTARIO!A81) -> EST-083 | B84: =IF(INVENTARIO!G81="","",INVENTARIO!G81) -> 3x1.20 | C84: =IF(INVENTARIO!B81="","",INVENTARIO!B81) -> Comedor principal | D84: =IF(INVENTARIO!D81="","",INVENTARIO!D81) -> Mesa de madera grande 14 sillas | E84: =IF(INVENTARIO!O82="","",INVENTARIO!O82) | F84: =IF(INVENTARIO!Q82="","",INVENTARIO!Q82) | G84: =IF(OR(E84="",F84=""),"",E84-F84) | H84: =IF(INVENTARIO!T82="","",INVENTARIO!T82) | I84: =IF(INVENTARIO!U82="","",INVENTARIO!U82) | J84: =IF(INVENTARIO!V82="","",INVENTARIO!V82) | K84: =IF(INVENTARIO!R82="","",INVENTARIO!R82) | L84: =IF(INVENTARIO!Y82="","",INVENTARIO!Y82)
A85: =IF(INVENTARIO!A82="","",INVENTARIO!A82) -> EST-084 | B85: =IF(INVENTARIO!G82="","",INVENTARIO!G82) -> 2x1 | C85: =IF(INVENTARIO!B82="","",INVENTARIO!B82) -> Comedor principal | D85: =IF(INVENTARIO!D82="","",INVENTARIO!D82) -> Mesa de apoyo de madera | E85: =IF(INVENTARIO!O83="","",INVENTARIO!O83) | F85: =IF(INVENTARIO!Q83="","",INVENTARIO!Q83) | G85: =IF(OR(E85="",F85=""),"",E85-F85) | H85: =IF(INVENTARIO!T83="","",INVENTARIO!T83) | I85: =IF(INVENTARIO!U83="","",INVENTARIO!U83) | J85: =IF(INVENTARIO!V83="","",INVENTARIO!V83) | K85: =IF(INVENTARIO!R83="","",INVENTARIO!R83) | L85: =IF(INVENTARIO!Y83="","",INVENTARIO!Y83)
A86: =IF(INVENTARIO!A83="","",INVENTARIO!A83) -> EST-085 | B86: =IF(INVENTARIO!G83="","",INVENTARIO!G83) -> 1.5x2.3.65 | C86: =IF(INVENTARIO!B83="","",INVENTARIO!B83) -> Comedor principal | D86: =IF(INVENTARIO!D83="","",INVENTARIO!D83) -> Mueble de apoyo vintage | E86: =IF(INVENTARIO!O84="","",INVENTARIO!O84) | F86: =IF(INVENTARIO!Q84="","",INVENTARIO!Q84) | G86: =IF(OR(E86="",F86=""),"",E86-F86) | H86: =IF(INVENTARIO!T84="","",INVENTARIO!T84) | I86: =IF(INVENTARIO!U84="","",INVENTARIO!U84) | J86: =IF(INVENTARIO!V84="","",INVENTARIO!V84) | K86: =IF(INVENTARIO!R84="","",INVENTARIO!R84) | L86: =IF(INVENTARIO!Y84="","",INVENTARIO!Y84)
A87: =IF(#REF!="","",#REF!) -> #REF! | B87: =IF(#REF!="","",#REF!) -> #REF! | C87: =IF(#REF!="","",#REF!) -> #REF! | D87: =IF(#REF!="","",#REF!) -> #REF! | E87: =IF(#REF!="","",#REF!) -> #REF! | F87: =IF(#REF!="","",#REF!) -> #REF! | G87: =IF(OR(E87="",F87=""),"",E87-F87) -> #REF! | H87: =IF(#REF!="","",#REF!) -> #REF! | I87: =IF(#REF!="","",#REF!) -> #REF! | J87: =IF(#REF!="","",#REF!) -> #REF! | K87: =IF(#REF!="","",#REF!) -> #REF! | L87: =IF(#REF!="","",#REF!) -> #REF!
A88: =IF(#REF!="","",#REF!) -> #REF! | B88: =IF(#REF!="","",#REF!) -> #REF! | C88: =IF(#REF!="","",#REF!) -> #REF! | D88: =IF(#REF!="","",#REF!) -> #REF! | E88: =IF(#REF!="","",#REF!) -> #REF! | F88: =IF(#REF!="","",#REF!) -> #REF! | G88: =IF(OR(E88="",F88=""),"",E88-F88) -> #REF! | H88: =IF(#REF!="","",#REF!) -> #REF! | I88: =IF(#REF!="","",#REF!) -> #REF! | J88: =IF(#REF!="","",#REF!) -> #REF! | K88: =IF(#REF!="","",#REF!) -> #REF! | L88: =IF(#REF!="","",#REF!) -> #REF!
A89: =IF(INVENTARIO!A84="","",INVENTARIO!A84) -> EST-088 | B89: =IF(INVENTARIO!G84="","",INVENTARIO!G84) -> 1.20 | C89: =IF(INVENTARIO!B84="","",INVENTARIO!B84) -> Sector Bar | D89: =IF(INVENTARIO!D84="","",INVENTARIO!D84) -> Mesa redonda madera grande | E89: =IF(INVENTARIO!O85="","",INVENTARIO!O85) | F89: =IF(INVENTARIO!Q85="","",INVENTARIO!Q85) | G89: =IF(OR(E89="",F89=""),"",E89-F89) | H89: =IF(INVENTARIO!T85="","",INVENTARIO!T85) | I89: =IF(INVENTARIO!U85="","",INVENTARIO!U85) | J89: =IF(INVENTARIO!V85="","",INVENTARIO!V85) | K89: =IF(INVENTARIO!R85="","",INVENTARIO!R85) | L89: =IF(INVENTARIO!Y85="","",INVENTARIO!Y85)
A90: =IF(INVENTARIO!A85="","",INVENTARIO!A85) -> EST-089 | B90: =IF(INVENTARIO!G85="","",INVENTARIO!G85) | C90: =IF(INVENTARIO!B85="","",INVENTARIO!B85) -> Sector Bar | D90: =IF(INVENTARIO!D85="","",INVENTARIO!D85) -> Sillas X5 | E90: =IF(INVENTARIO!O86="","",INVENTARIO!O86) | F90: =IF(INVENTARIO!Q86="","",INVENTARIO!Q86) | G90: =IF(OR(E90="",F90=""),"",E90-F90) | H90: =IF(INVENTARIO!T86="","",INVENTARIO!T86) | I90: =IF(INVENTARIO!U86="","",INVENTARIO!U86) | J90: =IF(INVENTARIO!V86="","",INVENTARIO!V86) | K90: =IF(INVENTARIO!R86="","",INVENTARIO!R86) | L90: =IF(INVENTARIO!Y86="","",INVENTARIO!Y86)
A91: =IF(INVENTARIO!A86="","",INVENTARIO!A86) -> EST-090 | B91: =IF(INVENTARIO!G86="","",INVENTARIO!G86) | C91: =IF(INVENTARIO!B86="","",INVENTARIO!B86) -> Sector Bar | D91: =IF(INVENTARIO!D86="","",INVENTARIO!D86) -> Banquetas barra | E91: =IF(INVENTARIO!O87="","",INVENTARIO!O87) | F91: =IF(INVENTARIO!Q87="","",INVENTARIO!Q87) | G91: =IF(OR(E91="",F91=""),"",E91-F91) | H91: =IF(INVENTARIO!T87="","",INVENTARIO!T87) | I91: =IF(INVENTARIO!U87="","",INVENTARIO!U87) | J91: =IF(INVENTARIO!V87="","",INVENTARIO!V87) | K91: =IF(INVENTARIO!R87="","",INVENTARIO!R87) | L91: =IF(INVENTARIO!Y87="","",INVENTARIO!Y87)
A92: =IF(INVENTARIO!A87="","",INVENTARIO!A87) -> EST-091 | B92: =IF(INVENTARIO!G87="","",INVENTARIO!G87) | C92: =IF(INVENTARIO!B87="","",INVENTARIO!B87) -> Sector bar | D92: =IF(INVENTARIO!D87="","",INVENTARIO!D87) -> Tromen grande | E92: =IF(INVENTARIO!O88="","",INVENTARIO!O88) | F92: =IF(INVENTARIO!Q88="","",INVENTARIO!Q88) | G92: =IF(OR(E92="",F92=""),"",E92-F92) | H92: =IF(INVENTARIO!T88="","",INVENTARIO!T88) | I92: =IF(INVENTARIO!U88="","",INVENTARIO!U88) | J92: =IF(INVENTARIO!V88="","",INVENTARIO!V88) | K92: =IF(INVENTARIO!R88="","",INVENTARIO!R88) | L92: =IF(INVENTARIO!Y88="","",INVENTARIO!Y88)
A93: =IF(INVENTARIO!A88="","",INVENTARIO!A88) -> EST-092 | B93: =IF(INVENTARIO!G88="","",INVENTARIO!G88) | C93: =IF(INVENTARIO!B88="","",INVENTARIO!B88) | D93: =IF(INVENTARIO!D88="","",INVENTARIO!D88) | E93: =IF(INVENTARIO!O89="","",INVENTARIO!O89) | F93: =IF(INVENTARIO!Q89="","",INVENTARIO!Q89) | G93: =IF(OR(E93="",F93=""),"",E93-F93) | H93: =IF(INVENTARIO!T89="","",INVENTARIO!T89) | I93: =IF(INVENTARIO!U89="","",INVENTARIO!U89) | J93: =IF(INVENTARIO!V89="","",INVENTARIO!V89) | K93: =IF(INVENTARIO!R89="","",INVENTARIO!R89) | L93: =IF(INVENTARIO!Y89="","",INVENTARIO!Y89)
A94: =IF(INVENTARIO!A89="","",INVENTARIO!A89) -> EST-093 | B94: =IF(INVENTARIO!G89="","",INVENTARIO!G89) | C94: =IF(INVENTARIO!B89="","",INVENTARIO!B89) | D94: =IF(INVENTARIO!D89="","",INVENTARIO!D89) | E94: =IF(INVENTARIO!O90="","",INVENTARIO!O90) | F94: =IF(INVENTARIO!Q90="","",INVENTARIO!Q90) | G94: =IF(OR(E94="",F94=""),"",E94-F94) | H94: =IF(INVENTARIO!T90="","",INVENTARIO!T90) | I94: =IF(INVENTARIO!U90="","",INVENTARIO!U90) | J94: =IF(INVENTARIO!V90="","",INVENTARIO!V90) | K94: =IF(INVENTARIO!R90="","",INVENTARIO!R90) | L94: =IF(INVENTARIO!Y90="","",INVENTARIO!Y90)
A95: =IF(INVENTARIO!A90="","",INVENTARIO!A90) -> EST-094 | B95: =IF(INVENTARIO!G90="","",INVENTARIO!G90) -> 60x57x85 | C95: =IF(INVENTARIO!B90="","",INVENTARIO!B90) -> Lavadero | D95: =IF(INVENTARIO!D90="","",INVENTARIO!D90) -> Lavarropas LG | E95: =IF(INVENTARIO!O91="","",INVENTARIO!O91) | F95: =IF(INVENTARIO!Q91="","",INVENTARIO!Q91) | G95: =IF(OR(E95="",F95=""),"",E95-F95) | H95: =IF(INVENTARIO!T91="","",INVENTARIO!T91) | I95: =IF(INVENTARIO!U91="","",INVENTARIO!U91) | J95: =IF(INVENTARIO!V91="","",INVENTARIO!V91) | K95: =IF(INVENTARIO!R91="","",INVENTARIO!R91) | L95: =IF(INVENTARIO!Y91="","",INVENTARIO!Y91)
A96: =IF(INVENTARIO!A91="","",INVENTARIO!A91) -> EST-095 | B96: =IF(INVENTARIO!G91="","",INVENTARIO!G91) -> 60x55x85 | C96: =IF(INVENTARIO!B91="","",INVENTARIO!B91) -> Lavadero | D96: =IF(INVENTARIO!D91="","",INVENTARIO!D91) -> Lavarropas Drean | E96: =IF(INVENTARIO!O92="","",INVENTARIO!O92) | F96: =IF(INVENTARIO!Q92="","",INVENTARIO!Q92) | G96: =IF(OR(E96="",F96=""),"",E96-F96) | H96: =IF(INVENTARIO!T92="","",INVENTARIO!T92) | I96: =IF(INVENTARIO!U92="","",INVENTARIO!U92) | J96: =IF(INVENTARIO!V92="","",INVENTARIO!V92) | K96: =IF(INVENTARIO!R92="","",INVENTARIO!R92) | L96: =IF(INVENTARIO!Y92="","",INVENTARIO!Y92)
A97: =IF(INVENTARIO!A92="","",INVENTARIO!A92) -> EST-096 | B97: =IF(INVENTARIO!G92="","",INVENTARIO!G92) -> 60x55x85 | C97: =IF(INVENTARIO!B92="","",INVENTARIO!B92) -> Lavadero | D97: =IF(INVENTARIO!D92="","",INVENTARIO!D92) -> Lavarropas Drean | E97: =IF(INVENTARIO!O93="","",INVENTARIO!O93) | F97: =IF(INVENTARIO!Q93="","",INVENTARIO!Q93) | G97: =IF(OR(E97="",F97=""),"",E97-F97) | H97: =IF(INVENTARIO!T93="","",INVENTARIO!T93) | I97: =IF(INVENTARIO!U93="","",INVENTARIO!U93) | J97: =IF(INVENTARIO!V93="","",INVENTARIO!V93) | K97: =IF(INVENTARIO!R93="","",INVENTARIO!R93) | L97: =IF(INVENTARIO!Y93="","",INVENTARIO!Y93)
A98: =IF(INVENTARIO!A93="","",INVENTARIO!A93) -> EST-097 | B98: =IF(INVENTARIO!G93="","",INVENTARIO!G93) -> 60x55x85 | C98: =IF(INVENTARIO!B93="","",INVENTARIO!B93) -> Lavadero | D98: =IF(INVENTARIO!D93="","",INVENTARIO!D93) -> Lavarrolas Eslabon de Lujo | E98: =IF(INVENTARIO!O94="","",INVENTARIO!O94) | F98: =IF(INVENTARIO!Q94="","",INVENTARIO!Q94) | G98: =IF(OR(E98="",F98=""),"",E98-F98) | H98: =IF(INVENTARIO!T94="","",INVENTARIO!T94) | I98: =IF(INVENTARIO!U94="","",INVENTARIO!U94) | J98: =IF(INVENTARIO!V94="","",INVENTARIO!V94) | K98: =IF(INVENTARIO!R94="","",INVENTARIO!R94) | L98: =IF(INVENTARIO!Y94="","",INVENTARIO!Y94)
A99: =IF(INVENTARIO!A94="","",INVENTARIO!A94) -> EST-098 | B99: =IF(INVENTARIO!G94="","",INVENTARIO!G94) -> 60x55x85 | C99: =IF(INVENTARIO!B94="","",INVENTARIO!B94) -> Lavadero | D99: =IF(INVENTARIO!D94="","",INVENTARIO!D94) -> Secadora Philco | E99: =IF(INVENTARIO!O95="","",INVENTARIO!O95) | F99: =IF(INVENTARIO!Q95="","",INVENTARIO!Q95) | G99: =IF(OR(E99="",F99=""),"",E99-F99) | H99: =IF(INVENTARIO!T95="","",INVENTARIO!T95) | I99: =IF(INVENTARIO!U95="","",INVENTARIO!U95) | J99: =IF(INVENTARIO!V95="","",INVENTARIO!V95) | K99: =IF(INVENTARIO!R95="","",INVENTARIO!R95) | L99: =IF(INVENTARIO!Y95="","",INVENTARIO!Y95)
A100: =IF(INVENTARIO!A95="","",INVENTARIO!A95) -> EST-099 | B100: =IF(INVENTARIO!G95="","",INVENTARIO!G95) -> 1 Plaza | C100: =IF(INVENTARIO!B95="","",INVENTARIO!B95) -> Lavadero | D100: =IF(INVENTARIO!D95="","",INVENTARIO!D95) -> Sabanas blancas 1P | E100: =IF(INVENTARIO!O96="","",INVENTARIO!O96) | F100: =IF(INVENTARIO!Q96="","",INVENTARIO!Q96) | G100: =IF(OR(E100="",F100=""),"",E100-F100) | H100: =IF(INVENTARIO!T96="","",INVENTARIO!T96) | I100: =IF(INVENTARIO!U96="","",INVENTARIO!U96) | J100: =IF(INVENTARIO!V96="","",INVENTARIO!V96) | K100: =IF(INVENTARIO!R96="","",INVENTARIO!R96) | L100: =IF(INVENTARIO!Y96="","",INVENTARIO!Y96)
... A105: =IF(INVENTARIO!A100="","",INVENTARIO!A100) -> EST-104 | B105: =IF(INVENTARIO!G100="","",INVENTARIO!G100) | C105: =IF(INVENTARIO!B100="","",INVENTARIO!B100) -> Lavadero | D105: =IF(INVENTARIO!D100="","",INVENTARIO!D100) -> Repasadores | E105: =IF(INVENTARIO!O101="","",INVENTARIO!O101) | F105: =IF(INVENTARIO!Q101="","",INVENTARIO!Q101) | G105: =IF(OR(E105="",F105=""),"",E105-F105) | H105: =IF(INVENTARIO!T101="","",INVENTARIO!T101) | I105: =IF(INVENTARIO!U101="","",INVENTARIO!U101) | J105: =IF(INVENTARIO!V101="","",INVENTARIO!V101) | K105: =IF(INVENTARIO!R101="","",INVENTARIO!R101) | L105: =IF(INVENTARIO!Y101="","",INVENTARIO!Y101)
A106: =IF(INVENTARIO!A101="","",INVENTARIO!A101) -> EST-105 | B106: =IF(INVENTARIO!G101="","",INVENTARIO!G101) | C106: =IF(INVENTARIO!B101="","",INVENTARIO!B101) -> Lavadero | D106: =IF(INVENTARIO!D101="","",INVENTARIO!D101) -> Alfombra ducha | E106: =IF(#REF!="","",#REF!) -> #REF! | F106: =IF(#REF!="","",#REF!) -> #REF! | G106: =IF(OR(E106="",F106=""),"",E106-F106) -> #REF! | H106: =IF(#REF!="","",#REF!) -> #REF! | I106: =IF(#REF!="","",#REF!) -> #REF! | J106: =IF(#REF!="","",#REF!) -> #REF! | K106: =IF(#REF!="","",#REF!) -> #REF! | L106: =IF(#REF!="","",#REF!) -> #REF!
A107: =IF(#REF!="","",#REF!) -> #REF! | B107: =IF(#REF!="","",#REF!) -> #REF! | C107: =IF(#REF!="","",#REF!) -> #REF! | D107: =IF(#REF!="","",#REF!) -> #REF! | E107: =IF(#REF!="","",#REF!) -> #REF! | F107: =IF(#REF!="","",#REF!) -> #REF! | G107: =IF(OR(E107="",F107=""),"",E107-F107) -> #REF! | H107: =IF(#REF!="","",#REF!) -> #REF! | I107: =IF(#REF!="","",#REF!) -> #REF! | J107: =IF(#REF!="","",#REF!) -> #REF! | K107: =IF(#REF!="","",#REF!) -> #REF! | L107: =IF(#REF!="","",#REF!) -> #REF!
...

Sheet CATALOGO
A1: ID | B1: Artículo | C1: Ambiente | D1: Tipo | E1: Descripción | F1: Estado | G1: Nivel de valor | H1: Precio publicado | I1: Publicar | J1: Foto principal | K1: Fotos adicionales | L1: Observaciones
A2: =IF(INVENTARIO!A2="","",INVENTARIO!A2) -> EST-001 | B2: =IF(INVENTARIO!G2="","",INVENTARIO!G2) -> 2 Plazas | C2: =IF(INVENTARIO!B2="","",INVENTARIO!B2) -> Dormitorio 2 | D2: =IF(INVENTARIO!D2="","",INVENTARIO!D2) -> Sommier 2 Plazas | E2: =IF(INVENTARIO!H2="","",INVENTARIO!H2) | F2: =IF(INVENTARIO!L2="","",INVENTARIO!L2) -> EST-001.jpg | G2: =IF(#REF!="","",#REF!) -> #REF! | H2: =IF(INVENTARIO!O2="","",INVENTARIO!O2) | I2: =IF(INVENTARIO!S2="","",INVENTARIO!S2) | J2: =IF(INVENTARIO!W2="","",INVENTARIO!W2) | K2: =IF(INVENTARIO!X2="","",INVENTARIO!X2) | L2: =IF(INVENTARIO!Y2="","",INVENTARIO!Y2)
A3: =IF(INVENTARIO!A3="","",INVENTARIO!A3) -> EST-002 | B3: =IF(INVENTARIO!G3="","",INVENTARIO!G3) -> 2 Plazas | C3: =IF(INVENTARIO!B3="","",INVENTARIO!B3) -> Dormitorio 2 | D3: =IF(INVENTARIO!D3="","",INVENTARIO!D3) -> Respaldo negro | E3: =IF(INVENTARIO!H3="","",INVENTARIO!H3) -> Buen estado | F3: =IF(INVENTARIO!L3="","",INVENTARIO!L3) -> EST-002.jpg | G3: =IF(#REF!="","",#REF!) -> #REF! | H3: =IF(INVENTARIO!O3="","",INVENTARIO!O3) | I3: =IF(INVENTARIO!S3="","",INVENTARIO!S3) | J3: =IF(INVENTARIO!W3="","",INVENTARIO!W3) | K3: =IF(INVENTARIO!X3="","",INVENTARIO!X3) | L3: =IF(INVENTARIO!Y3="","",INVENTARIO!Y3)
A4: =IF(INVENTARIO!A4="","",INVENTARIO!A4) -> EST-003 | B4: =IF(INVENTARIO!G4="","",INVENTARIO!G4) -> 43x31x65 | C4: =IF(INVENTARIO!B4="","",INVENTARIO!B4) -> Dormitorio 2 | D4: =IF(INVENTARIO!D4="","",INVENTARIO!D4) -> Mesa de luz Blanca | E4: =IF(INVENTARIO!H4="","",INVENTARIO!H4) -> Buen estado | F4: =IF(INVENTARIO!L4="","",INVENTARIO!L4) -> EST-003.jpg | G4: =IF(#REF!="","",#REF!) -> #REF! | H4: =IF(INVENTARIO!O4="","",INVENTARIO!O4) | I4: =IF(INVENTARIO!S4="","",INVENTARIO!S4) | J4: =IF(INVENTARIO!W4="","",INVENTARIO!W4) | K4: =IF(INVENTARIO!X4="","",INVENTARIO!X4) | L4: =IF(INVENTARIO!Y4="","",INVENTARIO!Y4)
A5: =IF(INVENTARIO!A5="","",INVENTARIO!A5) -> EST-004 | B5: =IF(INVENTARIO!G5="","",INVENTARIO!G5) -> 43x31x65 | C5: =IF(INVENTARIO!B5="","",INVENTARIO!B5) -> Dormitorio 2 | D5: =IF(INVENTARIO!D5="","",INVENTARIO!D5) -> Mesa de luz Blanca | E5: =IF(INVENTARIO!H5="","",INVENTARIO!H5) -> Despintada | F5: =IF(INVENTARIO!L5="","",INVENTARIO!L5) -> EST-004.jpg | G5: =IF(#REF!="","",#REF!) -> #REF! | H5: =IF(INVENTARIO!O5="","",INVENTARIO!O5) | I5: =IF(INVENTARIO!S5="","",INVENTARIO!S5) | J5: =IF(INVENTARIO!W5="","",INVENTARIO!W5) | K5: =IF(INVENTARIO!X5="","",INVENTARIO!X5) | L5: =IF(INVENTARIO!Y5="","",INVENTARIO!Y5)
A6: =IF(INVENTARIO!A6="","",INVENTARIO!A6) -> EST-005 | B6: =IF(INVENTARIO!G6="","",INVENTARIO!G6) | C6: =IF(INVENTARIO!B6="","",INVENTARIO!B6) -> Dormitorio 2 | D6: =IF(INVENTARIO!D6="","",INVENTARIO!D6) -> Velador artesanal | E6: =IF(INVENTARIO!H6="","",INVENTARIO!H6) -> Buen estado | F6: =IF(INVENTARIO!L6="","",INVENTARIO!L6) -> EST-005.jpg | G6: =IF(#REF!="","",#REF!) -> #REF! | H6: =IF(INVENTARIO!O6="","",INVENTARIO!O6) | I6: =IF(INVENTARIO!S6="","",INVENTARIO!S6) | J6: =IF(INVENTARIO!W6="","",INVENTARIO!W6) | K6: =IF(INVENTARIO!X6="","",INVENTARIO!X6) | L6: =IF(INVENTARIO!Y6="","",INVENTARIO!Y6)
A7: =IF(INVENTARIO!A7="","",INVENTARIO!A7) -> EST-006 | B7: =IF(INVENTARIO!G7="","",INVENTARIO!G7) | C7: =IF(INVENTARIO!B7="","",INVENTARIO!B7) -> Dormitorio 2 | D7: =IF(INVENTARIO!D7="","",INVENTARIO!D7) -> Cuadro caballo blanco | E7: =IF(INVENTARIO!H7="","",INVENTARIO!H7) -> Buen estado | F7: =IF(INVENTARIO!L7="","",INVENTARIO!L7) -> EST-006.jpg | G7: =IF(#REF!="","",#REF!) -> #REF! | H7: =IF(INVENTARIO!O7="","",INVENTARIO!O7) | I7: =IF(INVENTARIO!S7="","",INVENTARIO!S7) | J7: =IF(INVENTARIO!W7="","",INVENTARIO!W7) | K7: =IF(INVENTARIO!X7="","",INVENTARIO!X7) | L7: =IF(INVENTARIO!Y7="","",INVENTARIO!Y7)
A8: =IF(INVENTARIO!A8="","",INVENTARIO!A8) -> EST-007 | B8: =IF(INVENTARIO!G8="","",INVENTARIO!G8) | C8: =IF(INVENTARIO!B8="","",INVENTARIO!B8) -> Dormitorio 2 | D8: =IF(INVENTARIO!D8="","",INVENTARIO!D8) -> Cuna + Cambiador + Cajonera | E8: =IF(INVENTARIO!H8="","",INVENTARIO!H8) -> Sin detalles | F8: =IF(INVENTARIO!L8="","",INVENTARIO!L8) -> EST-007.jpg | G8: =IF(#REF!="","",#REF!) -> #REF! | H8: =IF(INVENTARIO!O8="","",INVENTARIO!O8) | I8: =IF(INVENTARIO!S8="","",INVENTARIO!S8) | J8: =IF(INVENTARIO!W8="","",INVENTARIO!W8) | K8: =IF(INVENTARIO!X8="","",INVENTARIO!X8) | L8: =IF(INVENTARIO!Y8="","",INVENTARIO!Y8)
A9: =IF(INVENTARIO!A9="","",INVENTARIO!A9) -> EST-008 | B9: =IF(INVENTARIO!G9="","",INVENTARIO!G9) | C9: =IF(INVENTARIO!B9="","",INVENTARIO!B9) -> Dormitorio 2 | D9: =IF(INVENTARIO!D9="","",INVENTARIO!D9) -> Escritorio | E9: =IF(INVENTARIO!H9="","",INVENTARIO!H9) -> Buen estado | F9: =IF(INVENTARIO!L9="","",INVENTARIO!L9) -> EST-008.jpg | G9: =IF(#REF!="","",#REF!) -> #REF! | H9: =IF(INVENTARIO!O9="","",INVENTARIO!O9) | I9: =IF(INVENTARIO!S9="","",INVENTARIO!S9) | J9: =IF(INVENTARIO!W9="","",INVENTARIO!W9) | K9: =IF(INVENTARIO!X9="","",INVENTARIO!X9) | L9: =IF(INVENTARIO!Y9="","",INVENTARIO!Y9)
A10: =IF(INVENTARIO!A10="","",INVENTARIO!A10) -> EST-009 | B10: =IF(INVENTARIO!G10="","",INVENTARIO!G10) | C10: =IF(INVENTARIO!B10="","",INVENTARIO!B10) -> Dormitorio 2 | D10: =IF(INVENTARIO!D10="","",INVENTARIO!D10) -> Sillon Matero de un cuerpo | E10: =IF(INVENTARIO!H10="","",INVENTARIO!H10) -> Buen estado | F10: =IF(INVENTARIO!L10="","",INVENTARIO!L10) -> EST-009.jpg | G10: =IF(#REF!="","",#REF!) -> #REF! | H10: =IF(INVENTARIO!O10="","",INVENTARIO!O10) | I10: =IF(INVENTARIO!S10="","",INVENTARIO!S10) | J10: =IF(INVENTARIO!W10="","",INVENTARIO!W10) | K10: =IF(INVENTARIO!X10="","",INVENTARIO!X10) | L10: =IF(INVENTARIO!Y10="","",INVENTARIO!Y10)
A11: =IF(INVENTARIO!A11="","",INVENTARIO!A11) -> EST-010 | B11: =IF(INVENTARIO!G11="","",INVENTARIO!G11) -> 32' | C11: =IF(INVENTARIO!B11="","",INVENTARIO!B11) -> Dormitorio 2 | D11: =IF(INVENTARIO!D11="","",INVENTARIO!D11) -> TV Admiral 32' | E11: =IF(INVENTARIO!H11="","",INVENTARIO!H11) -> Buen estado | F11: =IF(INVENTARIO!L11="","",INVENTARIO!L11) -> EST-010.jpg | G11: =IF(#REF!="","",#REF!) -> #REF! | H11: =IF(INVENTARIO!O11="","",INVENTARIO!O11) | I11: =IF(INVENTARIO!S11="","",INVENTARIO!S11) | J11: =IF(INVENTARIO!W11="","",INVENTARIO!W11) | K11: =IF(INVENTARIO!X11="","",INVENTARIO!X11) | L11: =IF(INVENTARIO!Y11="","",INVENTARIO!Y11)
A12: =IF(INVENTARIO!A12="","",INVENTARIO!A12) -> EST-011 | B12: =IF(INVENTARIO!G12="","",INVENTARIO!G12) | C12: =IF(INVENTARIO!B12="","",INVENTARIO!B12) -> Dormitorio 2 | D12: =IF(INVENTARIO!D12="","",INVENTARIO!D12) -> Estufa electrica ATMA | E12: =IF(INVENTARIO!H12="","",INVENTARIO!H12) -> Buen estado | F12: =IF(INVENTARIO!L12="","",INVENTARIO!L12) -> EST-011.jpg | G12: =IF(#REF!="","",#REF!) -> #REF! | H12: =IF(INVENTARIO!O12="","",INVENTARIO!O12) | I12: =IF(INVENTARIO!S12="","",INVENTARIO!S12) | J12: =IF(INVENTARIO!W12="","",INVENTARIO!W12) | K12: =IF(INVENTARIO!X12="","",INVENTARIO!X12) | L12: =IF(INVENTARIO!Y12="","",INVENTARIO!Y12)
A13: =IF(INVENTARIO!A13="","",INVENTARIO!A13) -> EST-012 | B13: =IF(INVENTARIO!G13="","",INVENTARIO!G13) -> 43x31x65 | C13: =IF(INVENTARIO!B13="","",INVENTARIO!B13) -> Dormitorio 3 | D13: =IF(INVENTARIO!D13="","",INVENTARIO!D13) -> Mesa de luz blanca | E13: =IF(INVENTARIO!H13="","",INVENTARIO!H13) -> Buen estado | F13: =IF(INVENTARIO!L13="","",INVENTARIO!L13) -> EST-012.jpg | G13: =IF(#REF!="","",#REF!) -> #REF! | H13: =IF(INVENTARIO!O13="","",INVENTARIO!O13) | I13: =IF(INVENTARIO!S13="","",INVENTARIO!S13) | J13: =IF(INVENTARIO!W13="","",INVENTARIO!W13) | K13: =IF(INVENTARIO!X13="","",INVENTARIO!X13) | L13: =IF(INVENTARIO!Y13="","",INVENTARIO!Y13)
... A77: =IF(INVENTARIO!A77="","",INVENTARIO!A77) -> EST-076 | B77: =IF(INVENTARIO!G77="","",INVENTARIO!G77) -> 200x100x50 | C77: =IF(INVENTARIO!B77="","",INVENTARIO!B77) -> Salon de juegos | D77: =IF(INVENTARIO!D77="","",INVENTARIO!D77) -> Mueble rustico | E77: =IF(INVENTARIO!H77="","",INVENTARIO!H77) -> Buen estado | F77: =IF(INVENTARIO!L77="","",INVENTARIO!L77) | G77: =IF(#REF!="","",#REF!) -> #REF! | H77: =IF(INVENTARIO!O77="","",INVENTARIO!O77) | I77: =IF(INVENTARIO!S77="","",INVENTARIO!S77) | J77: =IF(INVENTARIO!W77="","",INVENTARIO!W77) | K77: =IF(INVENTARIO!X77="","",INVENTARIO!X77) | L77: =IF(INVENTARIO!Y77="","",INVENTARIO!Y77)
A78: =IF(#REF!="","",#REF!) -> #REF! | B78: =IF(#REF!="","",#REF!) -> #REF! | C78: =IF(#REF!="","",#REF!) -> #REF! | D78: =IF(#REF!="","",#REF!) -> #REF! | E78: =IF(#REF!="","",#REF!) -> #REF! | F78: =IF(#REF!="","",#REF!) -> #REF! | G78: =IF(#REF!="","",#REF!) -> #REF! | H78: =IF(INVENTARIO!O78="","",INVENTARIO!O78) | I78: =IF(INVENTARIO!S78="","",INVENTARIO!S78) | J78: =IF(INVENTARIO!W78="","",INVENTARIO!W78) | K78: =IF(INVENTARIO!X78="","",INVENTARIO!X78) | L78: =IF(INVENTARIO!Y78="","",INVENTARIO!Y78)
A79: =IF(INVENTARIO!A78="","",INVENTARIO!A78) -> EST-078 | B79: =IF(INVENTARIO!G78="","",INVENTARIO!G78) -> 1.90x70 | C79: =IF(INVENTARIO!B78="","",INVENTARIO!B78) -> Resibidor | D79: =IF(INVENTARIO!D78="","",INVENTARIO!D78) -> Sillon 3 cuerpos floreado | E79: =IF(INVENTARIO!H78="","",INVENTARIO!H78) -> Buen estado | F79: =IF(INVENTARIO!L78="","",INVENTARIO!L78) | G79: =IF(#REF!="","",#REF!) -> #REF! | H79: =IF(INVENTARIO!O79="","",INVENTARIO!O79) | I79: =IF(INVENTARIO!S79="","",INVENTARIO!S79) | J79: =IF(INVENTARIO!W79="","",INVENTARIO!W79) | K79: =IF(INVENTARIO!X79="","",INVENTARIO!X79) | L79: =IF(INVENTARIO!Y79="","",INVENTARIO!Y79)
A80: =IF(INVENTARIO!A79="","",INVENTARIO!A79) -> EST-079 | B80: =IF(INVENTARIO!G79="","",INVENTARIO!G79) -> 1 M | C80: =IF(INVENTARIO!B79="","",INVENTARIO!B79) -> Resibidor | D80: =IF(INVENTARIO!D79="","",INVENTARIO!D79) -> Perchero de madera largo | E80: =IF(INVENTARIO!H79="","",INVENTARIO!H79) -> Buen estado | F80: =IF(INVENTARIO!L79="","",INVENTARIO!L79) | G80: =IF(#REF!="","",#REF!) -> #REF! | H80: =IF(INVENTARIO!O80="","",INVENTARIO!O80) | I80: =IF(INVENTARIO!S80="","",INVENTARIO!S80) | J80: =IF(INVENTARIO!W80="","",INVENTARIO!W80) | K80: =IF(INVENTARIO!X80="","",INVENTARIO!X80) | L80: =IF(INVENTARIO!Y80="","",INVENTARIO!Y80)
A81: =IF(INVENTARIO!A80="","",INVENTARIO!A80) -> EST-080 | B81: =IF(INVENTARIO!G80="","",INVENTARIO!G80) | C81: =IF(INVENTARIO!B80="","",INVENTARIO!B80) -> Resibidor | D81: =IF(INVENTARIO!D80="","",INVENTARIO!D80) -> Cuadro caballo | E81: =IF(INVENTARIO!H80="","",INVENTARIO!H80) -> Buen estado | F81: =IF(INVENTARIO!L80="","",INVENTARIO!L80) | G81: =IF(#REF!="","",#REF!) -> #REF! | H81: =IF(INVENTARIO!O81="","",INVENTARIO!O81) | I81: =IF(INVENTARIO!S81="","",INVENTARIO!S81) | J81: =IF(INVENTARIO!W81="","",INVENTARIO!W81) | K81: =IF(INVENTARIO!X81="","",INVENTARIO!X81) | L81: =IF(INVENTARIO!Y81="","",INVENTARIO!Y81)
A82: =IF(#REF!="","",#REF!) -> #REF! | B82: =IF(#REF!="","",#REF!) -> #REF! | C82: =IF(#REF!="","",#REF!) -> #REF! | D82: =IF(#REF!="","",#REF!) -> #REF! | E82: =IF(#REF!="","",#REF!) -> #REF! | F82: =IF(#REF!="","",#REF!) -> #REF! | G82: =IF(#REF!="","",#REF!) -> #REF! | H82: =IF(#REF!="","",#REF!) -> #REF! | ... L82: =IF(#REF!="","",#REF!) -> #REF!
A83: =IF(#REF!="","",#REF!) -> #REF! | B83: =IF(#REF!="","",#REF!) -> #REF! | C83: =IF(#REF!="","",#REF!) -> #REF! | D83: =IF(#REF!="","",#REF!) -> #REF! | E83: =IF(#REF!="","",#REF!) -> #REF! | F83: =IF(#REF!="","",#REF!) -> #REF! | G83: =IF(#REF!="","",#REF!) -> #REF! | H83: =IF(#REF!="","",#REF!) -> #REF! | ... L83: =IF(#REF!="","",#REF!) -> #REF!
A84: =IF(INVENTARIO!A81="","",INVENTARIO!A81) -> EST-083 | B84: =IF(INVENTARIO!G81="","",INVENTARIO!G81) -> 3x1.20 | C84: =IF(INVENTARIO!B81="","",INVENTARIO!B81) -> Comedor principal | D84: =IF(INVENTARIO!D81="","",INVENTARIO!D81) -> Mesa de madera grande 14 sillas | E84: =IF(INVENTARIO!H81="","",INVENTARIO!H81) -> Buen estado | F84: =IF(INVENTARIO!L81="","",INVENTARIO!L81) | G84: =IF(#REF!="","",#REF!) -> #REF! | H84: =IF(INVENTARIO!O82="","",INVENTARIO!O82) | I84: =IF(INVENTARIO!S82="","",INVENTARIO!S82) | J84: =IF(INVENTARIO!W82="","",INVENTARIO!W82) | K84: =IF(INVENTARIO!X82="","",INVENTARIO!X82) | L84: =IF(INVENTARIO!Y82="","",INVENTARIO!Y82)
A85: =IF(INVENTARIO!A82="","",INVENTARIO!A82) -> EST-084 | B85: =IF(INVENTARIO!G82="","",INVENTARIO!G82) -> 2x1 | C85: =IF(INVENTARIO!B82="","",INVENTARIO!B82) -> Comedor principal | D85: =IF(INVENTARIO!D82="","",INVENTARIO!D82) -> Mesa de apoyo de madera | E85: =IF(INVENTARIO!H82="","",INVENTARIO!H82) -> Buen estado | F85: =IF(INVENTARIO!L82="","",INVENTARIO!L82) | G85: =IF(#REF!="","",#REF!) -> #REF! | H85: =IF(INVENTARIO!O83="","",INVENTARIO!O83) | I85: =IF(INVENTARIO!S83="","",INVENTARIO!S83) | J85: =IF(INVENTARIO!W83="","",INVENTARIO!W83) | K85: =IF(INVENTARIO!X83="","",INVENTARIO!X83) | L85: =IF(INVENTARIO!Y83="","",INVENTARIO!Y83)
A86: =IF(INVENTARIO!A83="","",INVENTARIO!A83) -> EST-085 | B86: =IF(INVENTARIO!G83="","",INVENTARIO!G83) -> 1.5x2.3.65 | C86: =IF(INVENTARIO!B83="","",INVENTARIO!B83) -> Comedor principal | D86: =IF(INVENTARIO!D83="","",INVENTARIO!D83) -> Mueble de apoyo vintage | E86: =IF(INVENTARIO!H83="","",INVENTARIO!H83) -> Buen estado | F86: =IF(INVENTARIO!L83="","",INVENTARIO!L83) | G86: =IF(#REF!="","",#REF!) -> #REF! | H86: =IF(INVENTARIO!O84="","",INVENTARIO!O84) | I86: =IF(INVENTARIO!S84="","",INVENTARIO!S84) | J86: =IF(INVENTARIO!W84="","",INVENTARIO!W84) | K86: =IF(INVENTARIO!X84="","",INVENTARIO!X84) | L86: =IF(INVENTARIO!Y84="","",INVENTARIO!Y84)
A87: =IF(#REF!="","",#REF!) -> #REF! | B87: =IF(#REF!="","",#REF!) -> #REF! | C87: =IF(#REF!="","",#REF!) -> #REF! | D87: =IF(#REF!="","",#REF!) -> #REF! | E87: =IF(#REF!="","",#REF!) -> #REF! | F87: =IF(#REF!="","",#REF!) -> #REF! | G87: =IF(#REF!="","",#REF!) -> #REF! | H87: =IF(#REF!="","",#REF!) -> #REF! | ... L87: =IF(#REF!="","",#REF!) -> #REF!
A88: =IF(#REF!="","",#REF!) -> #REF! | B88: =IF(#REF!="","",#REF!) -> #REF! | C88: =IF(#REF!="","",#REF!) -> #REF! | D88: =IF(#REF!="","",#REF!) -> #REF! | E88: =IF(#REF!="","",#REF!) -> #REF! | F88: =IF(#REF!="","",#REF!) -> #REF! | G88: =IF(#REF!="","",#REF!) -> #REF! | H88: =IF(#REF!="","",#REF!) -> #REF! | ... L88: =IF(#REF!="","",#REF!) -> #REF!
A89: =IF(INVENTARIO!A84="","",INVENTARIO!A84) -> EST-088 | B89: =IF(INVENTARIO!G84="","",INVENTARIO!G84) -> 1.20 | C89: =IF(INVENTARIO!B84="","",INVENTARIO!B84) -> Sector Bar | D89: =IF(INVENTARIO!D84="","",INVENTARIO!D84) -> Mesa redonda madera grande | E89: =IF(INVENTARIO!H84="","",INVENTARIO!H84) -> Buen estado | F89: =IF(INVENTARIO!L84="","",INVENTARIO!L84) | G89: =IF(#REF!="","",#REF!) -> #REF! | H89: =IF(INVENTARIO!O85="","",INVENTARIO!O85) | I89: =IF(INVENTARIO!S85="","",INVENTARIO!S85) | J89: =IF(INVENTARIO!W85="","",INVENTARIO!W85) | K89: =IF(INVENTARIO!X85="","",INVENTARIO!X85) | L89: =IF(INVENTARIO!Y85="","",INVENTARIO!Y85)
A90: =IF(INVENTARIO!A85="","",INVENTARIO!A85) -> EST-089 | B90: =IF(INVENTARIO!G85="","",INVENTARIO!G85) | C90: =IF(INVENTARIO!B85="","",INVENTARIO!B85) -> Sector Bar | D90: =IF(INVENTARIO!D85="","",INVENTARIO!D85) -> Sillas X5 | E90: =IF(INVENTARIO!H85="","",INVENTARIO!H85) -> Buen estado | F90: =IF(INVENTARIO!L85="","",INVENTARIO!L85) | G90: =IF(#REF!="","",#REF!) -> #REF! | H90: =IF(INVENTARIO!O86="","",INVENTARIO!O86) | I90: =IF(INVENTARIO!S86="","",INVENTARIO!S86) | J90: =IF(INVENTARIO!W86="","",INVENTARIO!W86) | K90: =IF(INVENTARIO!X86="","",INVENTARIO!X86) | L90: =IF(INVENTARIO!Y86="","",INVENTARIO!Y86)
A91: =IF(INVENTARIO!A86="","",INVENTARIO!A86) -> EST-090 | B91: =IF(INVENTARIO!G86="","",INVENTARIO!G86) | C91: =IF(INVENTARIO!B86="","",INVENTARIO!B86) -> Sector Bar | D91: =IF(INVENTARIO!D86="","",INVENTARIO!D86) -> Banquetas barra | E91: =IF(INVENTARIO!H86="","",INVENTARIO!H86) -> Buen estado | F91: =IF(INVENTARIO!L86="","",INVENTARIO!L86) | G91: =IF(#REF!="","",#REF!) -> #REF! | H91: =IF(INVENTARIO!O87="","",INVENTARIO!O87) | I91: =IF(INVENTARIO!S87="","",INVENTARIO!S87) | J91: =IF(INVENTARIO!W87="","",INVENTARIO!W87) | K91: =IF(INVENTARIO!X87="","",INVENTARIO!X87) | L91: =IF(INVENTARIO!Y87="","",INVENTARIO!Y87)
A92: =IF(INVENTARIO!A87="","",INVENTARIO!A87) -> EST-091 | B92: =IF(INVENTARIO!G87="","",INVENTARIO!G87) | C92: =IF(INVENTARIO!B87="","",INVENTARIO!B87) -> Sector bar | D92: =IF(INVENTARIO!D87="","",INVENTARIO!D87) -> Tromen grande | E92: =IF(INVENTARIO!H87="","",INVENTARIO!H87) -> Buen estado | F92: =IF(INVENTARIO!L87="","",INVENTARIO!L87) | G92: =IF(#REF!="","",#REF!) -> #REF! | H92: =IF(INVENTARIO!O88="","",INVENTARIO!O88) | I92: =IF(INVENTARIO!S88="","",INVENTARIO!S88) | J92: =IF(INVENTARIO!W88="","",INVENTARIO!W88) | K92: =IF(INVENTARIO!X88="","",INVENTARIO!X88) | L92: =IF(INVENTARIO!Y88="","",INVENTARIO!Y88)
